(replit_env) F:\Saram Work\navi_backend_2>python run_fastapi.py
Traceback (most recent call last):
  File "F:\Saram Work\navi_backend_2\run_fastapi.py", line 6, in <module>
    app = create_fastapi_app()
  File "F:\Saram Work\navi_backend_2\main.py", line 105, in create_fastapi_app
    from endpoints.auth import router as auth_router
  File "F:\Saram Work\navi_backend_2\endpoints\auth.py", line 8, in <module>
    from models.user import UserCreate, UserResponse, UserLogin, UserOTPVerify, UserPasswordReset, UserPasswordResetConfirm, Token
  File "F:\Saram Work\navi_backend_2\models\user.py", line 4, in <module>
    from pymongo.bson import ObjectId
ModuleNotFoundError: No module named 'pymongo.bson'

(replit_env) F:\Saram Work\navi_backend_2>python run_fastapi.py
Traceback (most recent call last):
  File "F:\Saram Work\navi_backend_2\run_fastapi.py", line 6, in <module>
    app = create_fastapi_app()
  File "F:\Saram Work\navi_backend_2\main.py", line 107, in create_fastapi_app
    from endpoints.appointments import router as appointments_router
  File "F:\Saram Work\navi_backend_2\endpoints\appointments.py", line 6, in <module>
    from models.appointment import AppointmentCreate, AppointmentResponse, AppointmentUpdate, AppointmentStatus, PaymentStatus
  File "F:\Saram Work\navi_backend_2\models\appointment.py", line 5, in <module>
    from pymongo.bson import ObjectId
ModuleNotFoundError: No module named 'pymongo.bson'

(replit_env) F:\Saram Work\navi_backend_2>python run_fastapi.py
INFO:     Started server process [38428]
INFO:     Waiting for application startup.
INFO:db.database:Connecting to MongoDB Atlas...
INFO:db.database:Connected to MongoDB Atlas successfully
ERROR:    Traceback (most recent call last):
  File "F:\Saram Work\navi_backend_2\replit_env\Lib\site-packages\pymongo\pool.py", line 767, in command
    return command(
        self,
    ...<20 lines>...
        write_concern=write_concern,
    )
  File "F:\Saram Work\navi_backend_2\replit_env\Lib\site-packages\pymongo\network.py", line 156, in command
    reply = receive_message(sock_info, request_id)
  File "F:\Saram Work\navi_backend_2\replit_env\Lib\site-packages\pymongo\network.py", line 217, in receive_message
    _receive_data_on_socket(sock_info, 16, deadline)
    ~~~~~~~~~~~~~~~~~~~~~~~^^^^^^^^^^^^^^^^^^^^^^^^^
  File "F:\Saram Work\navi_backend_2\replit_env\Lib\site-packages\pymongo\network.py", line 299, in _receive_data_on_socket
    chunk_length = sock_info.sock.recv_into(mv[bytes_read:])
  File "C:\Python313\Lib\ssl.py", line 1304, in recv_into
    return self.read(nbytes, buffer)
           ~~~~~~~~~^^^^^^^^^^^^^^^^
  File "C:\Python313\Lib\ssl.py", line 1138, in read
    return self._sslobj.read(len, buffer)
           ~~~~~~~~~~~~~~~~~^^^^^^^^^^^^^
ConnectionResetError: [WinError 10054] An existing connection was forcibly closed by the remote host

The above exception was the direct cause of the following exception:

Traceback (most recent call last):
  File "F:\Saram Work\navi_backend_2\replit_env\Lib\site-packages\starlette\routing.py", line 692, in lifespan
    async with self.lifespan_context(app) as maybe_state:
               ~~~~~~~~~~~~~~~~~~~~~^^^^^
  File "C:\Python313\Lib\contextlib.py", line 214, in __aenter__
    return await anext(self.gen)
           ^^^^^^^^^^^^^^^^^^^^^
  File "F:\Saram Work\navi_backend_2\replit_env\Lib\site-packages\fastapi\routing.py", line 133, in merged_lifespan
    async with original_context(app) as maybe_original_state:
               ~~~~~~~~~~~~~~~~^^^^^
  File "C:\Python313\Lib\contextlib.py", line 214, in __aenter__
    return await anext(self.gen)
           ^^^^^^^^^^^^^^^^^^^^^
  File "F:\Saram Work\navi_backend_2\replit_env\Lib\site-packages\fastapi\routing.py", line 133, in merged_lifespan
    async with original_context(app) as maybe_original_state:
               ~~~~~~~~~~~~~~~~^^^^^
  File "C:\Python313\Lib\contextlib.py", line 214, in __aenter__
    return await anext(self.gen)
           ^^^^^^^^^^^^^^^^^^^^^
  File "F:\Saram Work\navi_backend_2\replit_env\Lib\site-packages\fastapi\routing.py", line 133, in merged_lifespan
    async with original_context(app) as maybe_original_state:
               ~~~~~~~~~~~~~~~~^^^^^
  File "C:\Python313\Lib\contextlib.py", line 214, in __aenter__
    return await anext(self.gen)
           ^^^^^^^^^^^^^^^^^^^^^
  File "F:\Saram Work\navi_backend_2\replit_env\Lib\site-packages\fastapi\routing.py", line 133, in merged_lifespan
    async with original_context(app) as maybe_original_state:
               ~~~~~~~~~~~~~~~~^^^^^
  File "C:\Python313\Lib\contextlib.py", line 214, in __aenter__
    return await anext(self.gen)
           ^^^^^^^^^^^^^^^^^^^^^
  File "F:\Saram Work\navi_backend_2\replit_env\Lib\site-packages\fastapi\routing.py", line 133, in merged_lifespan
    async with original_context(app) as maybe_original_state:
               ~~~~~~~~~~~~~~~~^^^^^
  File "C:\Python313\Lib\contextlib.py", line 214, in __aenter__
    return await anext(self.gen)
           ^^^^^^^^^^^^^^^^^^^^^
  File "F:\Saram Work\navi_backend_2\replit_env\Lib\site-packages\fastapi\routing.py", line 133, in merged_lifespan
    async with original_context(app) as maybe_original_state:
               ~~~~~~~~~~~~~~~~^^^^^
  File "F:\Saram Work\navi_backend_2\replit_env\Lib\site-packages\starlette\routing.py", line 569, in __aenter__
    await self._router.startup()
  File "F:\Saram Work\navi_backend_2\replit_env\Lib\site-packages\starlette\routing.py", line 669, in startup
    await handler()
  File "F:\Saram Work\navi_backend_2\db\database.py", line 27, in connect_to_mongo
    await create_indexes()
  File "F:\Saram Work\navi_backend_2\db\database.py", line 72, in create_indexes
    await db.chatbot_conversations.create_index("timestamp")
  File "C:\Python313\Lib\concurrent\futures\thread.py", line 59, in run
    result = self.fn(*self.args, **self.kwargs)
  File "F:\Saram Work\navi_backend_2\replit_env\Lib\site-packages\pymongo\collection.py", line 2055, in create_index
    return self.__create_indexes([index], session, **cmd_options)[0]
           ~~~~~~~~~~~~~~~~~~~~~^^^^^^^^^^^^^^^^^^^^^^^^^^^^^^^^^
  File "F:\Saram Work\navi_backend_2\replit_env\Lib\site-packages\pymongo\_csot.py", line 105, in csot_wrapper
    return func(self, *args, **kwargs)
  File "F:\Saram Work\navi_backend_2\replit_env\Lib\site-packages\pymongo\collection.py", line 1932, in __create_indexes
    self._command(
    ~~~~~~~~~~~~~^
        sock_info,
        ^^^^^^^^^^
    ...<4 lines>...
        session=session,
        ^^^^^^^^^^^^^^^^
    )
    ^
  File "F:\Saram Work\navi_backend_2\replit_env\Lib\site-packages\pymongo\collection.py", line 292, in _command
    return sock_info.command(
           ~~~~~~~~~~~~~~~~~^
        self.__database.name,
        ^^^^^^^^^^^^^^^^^^^^^
    ...<12 lines>...
        user_fields=user_fields,
        ^^^^^^^^^^^^^^^^^^^^^^^^
    )
    ^
  File "F:\Saram Work\navi_backend_2\replit_env\Lib\site-packages\pymongo\pool.py", line 795, in command
    self._raise_connection_failure(error)
    ~~~~~~~~~~~~~~~~~~~~~~~~~~~~~~^^^^^^^
  File "F:\Saram Work\navi_backend_2\replit_env\Lib\site-packages\pymongo\pool.py", line 953, in _raise_connection_failure
    _raise_connection_failure(self.address, error)
    ~~~~~~~~~~~~~~~~~~~~~~~~~^^^^^^^^^^^^^^^^^^^^^
  File "F:\Saram Work\navi_backend_2\replit_env\Lib\site-packages\pymongo\pool.py", line 262, in _raise_connection_failure
    raise AutoReconnect(msg) from error
pymongo.errors.AutoReconnect: ac-vhoqmzw-shard-00-01.w2pocbl.mongodb.net:27017: [WinError 10054] An existing connection was forcibly closed by the remote host

ERROR:    Application startup failed. Exiting.

(replit_env) F:\Saram Work\navi_backend_2>python run_fastapi.py
INFO:     Started server process [9328]
INFO:     Waiting for application startup.
INFO:db.database:Connecting to MongoDB Atlas...
INFO:db.database:Connected to MongoDB Atlas successfully
INFO:db.database:Database indexes created successfully
INFO:     Application startup complete.
INFO:     Uvicorn running on http://0.0.0.0:5001 (Press CTRL+C to quit)
INFO:     127.0.0.1:52588 - "GET / HTTP/1.1" 200 OK
INFO:     127.0.0.1:52588 - "GET /favicon.ico HTTP/1.1" 404 Not Found
INFO:     127.0.0.1:52588 - "GET /DOCS HTTP/1.1" 404 Not Found
INFO:     127.0.0.1:52588 - "GET /docs HTTP/1.1" 200 OK
INFO:     127.0.0.1:52588 - "GET /openapi.json HTTP/1.1" 200 OK
WARNING:passlib.handlers.bcrypt:(trapped) error reading bcrypt version
Traceback (most recent call last):
  File "F:\Saram Work\navi_backend_2\replit_env\Lib\site-packages\passlib\handlers\bcrypt.py", line 620, in _load_backend_mixin
    version = _bcrypt.__about__.__version__
              ^^^^^^^^^^^^^^^^^
AttributeError: module 'bcrypt' has no attribute '__about__'
INFO:utils.email:Email would be sent to: ibtehajkhanoff@gmail.com
INFO:utils.email:Subject: Your OTP for Account Verification
INFO:utils.email:Body:
    Hello,

    Your One Time Password (OTP) for account verification is: 568208

    This OTP is valid for 10 minutes.

    If you didn't request this OTP, please ignore this email.

    Regards,
    The Clinic Team

WARNING:utils.email:Email credentials not configured. Email not sent.
INFO:     127.0.0.1:52608 - "POST /auth/register HTTP/1.1" 200 OK
INFO:     Shutting down
INFO:     Waiting for application shutdown.
INFO:db.database:Closing MongoDB connection...
INFO:db.database:MongoDB connection closed
INFO:     Application shutdown complete.
INFO:     Finished server process [9328]

(replit_env) F:\Saram Work\navi_backend_2>python run_fastapi.py
INFO:     Started server process [20392]
INFO:     Waiting for application startup.
INFO:db.database:Connecting to MongoDB Atlas...
INFO:db.database:Connected to MongoDB Atlas successfully
INFO:db.database:Database indexes created successfully
INFO:     Application startup complete.
INFO:     Uvicorn running on http://0.0.0.0:5001 (Press CTRL+C to quit)
INFO:     127.0.0.1:52670 - "POST /auth/register HTTP/1.1" 400 Bad Request
INFO:     127.0.0.1:52678 - "POST /auth/register HTTP/1.1" 400 Bad Request
WARNING:passlib.handlers.bcrypt:(trapped) error reading bcrypt version
Traceback (most recent call last):
  File "F:\Saram Work\navi_backend_2\replit_env\Lib\site-packages\passlib\handlers\bcrypt.py", line 620, in _load_backend_mixin
    version = _bcrypt.__about__.__version__
              ^^^^^^^^^^^^^^^^^
AttributeError: module 'bcrypt' has no attribute '__about__'
INFO:utils.email:Email sent successfully to talhasami.3285@gmail.com
INFO:     127.0.0.1:52679 - "POST /auth/register HTTP/1.1" 200 OK
INFO:     127.0.0.1:52695 - "POST /auth/verify HTTP/1.1" 200 OK
INFO:     127.0.0.1:52696 - "POST /auth/login/email HTTP/1.1" 200 OK
INFO:     127.0.0.1:52743 - "POST /auth/login HTTP/1.1" 200 OK
INFO:     127.0.0.1:52744 - "POST /auth/login HTTP/1.1" 401 Unauthorized
INFO:     127.0.0.1:52755 - "POST /auth/login HTTP/1.1" 200 OK
INFO:     127.0.0.1:52756 - "GET /auth/me HTTP/1.1" 500 Internal Server Error
ERROR:    Exception in ASGI application
Traceback (most recent call last):
  File "F:\Saram Work\navi_backend_2\replit_env\Lib\site-packages\uvicorn\protocols\http\h11_impl.py", line 403, in run_asgi
    result = await app(  # type: ignore[func-returns-value]
             ^^^^^^^^^^^^^^^^^^^^^^^^^^^^^^^^^^^^^^^^^^^^^^
        self.scope, self.receive, self.send
        ^^^^^^^^^^^^^^^^^^^^^^^^^^^^^^^^^^^
    )
    ^
  File "F:\Saram Work\navi_backend_2\replit_env\Lib\site-packages\uvicorn\middleware\proxy_headers.py", line 60, in __call__
    return await self.app(scope, receive, send)
           ^^^^^^^^^^^^^^^^^^^^^^^^^^^^^^^^^^^^
  File "F:\Saram Work\navi_backend_2\replit_env\Lib\site-packages\fastapi\applications.py", line 1054, in __call__
    await super().__call__(scope, receive, send)
  File "F:\Saram Work\navi_backend_2\replit_env\Lib\site-packages\starlette\applications.py", line 112, in __call__
    await self.middleware_stack(scope, receive, send)
  File "F:\Saram Work\navi_backend_2\replit_env\Lib\site-packages\starlette\middleware\errors.py", line 187, in __call__
    raise exc
  File "F:\Saram Work\navi_backend_2\replit_env\Lib\site-packages\starlette\middleware\errors.py", line 165, in __call__
    await self.app(scope, receive, _send)
  File "F:\Saram Work\navi_backend_2\replit_env\Lib\site-packages\starlette\middleware\cors.py", line 85, in __call__
    await self.app(scope, receive, send)
  File "F:\Saram Work\navi_backend_2\replit_env\Lib\site-packages\starlette\middleware\exceptions.py", line 62, in __call__
    await wrap_app_handling_exceptions(self.app, conn)(scope, receive, send)
  File "F:\Saram Work\navi_backend_2\replit_env\Lib\site-packages\starlette\_exception_handler.py", line 53, in wrapped_app
    raise exc
  File "F:\Saram Work\navi_backend_2\replit_env\Lib\site-packages\starlette\_exception_handler.py", line 42, in wrapped_app
    await app(scope, receive, sender)
  File "F:\Saram Work\navi_backend_2\replit_env\Lib\site-packages\starlette\routing.py", line 714, in __call__
    await self.middleware_stack(scope, receive, send)
  File "F:\Saram Work\navi_backend_2\replit_env\Lib\site-packages\starlette\routing.py", line 734, in app
    await route.handle(scope, receive, send)
  File "F:\Saram Work\navi_backend_2\replit_env\Lib\site-packages\starlette\routing.py", line 288, in handle
    await self.app(scope, receive, send)
  File "F:\Saram Work\navi_backend_2\replit_env\Lib\site-packages\starlette\routing.py", line 76, in app
    await wrap_app_handling_exceptions(app, request)(scope, receive, send)
  File "F:\Saram Work\navi_backend_2\replit_env\Lib\site-packages\starlette\_exception_handler.py", line 53, in wrapped_app
    raise exc
  File "F:\Saram Work\navi_backend_2\replit_env\Lib\site-packages\starlette\_exception_handler.py", line 42, in wrapped_app
    await app(scope, receive, sender)
  File "F:\Saram Work\navi_backend_2\replit_env\Lib\site-packages\starlette\routing.py", line 73, in app
    response = await f(request)
               ^^^^^^^^^^^^^^^^
  File "F:\Saram Work\navi_backend_2\replit_env\Lib\site-packages\fastapi\routing.py", line 327, in app
    content = await serialize_response(
              ^^^^^^^^^^^^^^^^^^^^^^^^^
    ...<9 lines>...
    )
    ^
  File "F:\Saram Work\navi_backend_2\replit_env\Lib\site-packages\fastapi\routing.py", line 176, in serialize_response
    raise ResponseValidationError(
        errors=_normalize_errors(errors), body=response_content
    )
fastapi.exceptions.ResponseValidationError: 1 validation errors:
  {'loc': ('response', '_id'), 'msg': 'str type expected', 'type': 'type_error.str'}

INFO:endpoints.chatbot:Received WhatsApp message from :
INFO:agents.chatbot_agent:Processing message from :
ERROR:agents.chatbot_agent:Error processing message: 'NoneType' object has no attribute 'users'
INFO:     127.0.0.1:52790 - "POST /chatbot/webhook HTTP/1.1" 200 OK
INFO:agents.chatbot_agent:Processing message from +testae2cc614: Hi
ERROR:agents.chatbot_agent:Error processing message: 'NoneType' object has no attribute 'users'
INFO:     127.0.0.1:52791 - "POST /chatbot/test-agent HTTP/1.1" 200 OK
INFO:endpoints.chatbot:Received WhatsApp message from :
INFO:agents.chatbot_agent:Processing message from :
ERROR:agents.chatbot_agent:Error processing message: 'NoneType' object has no attribute 'users'
INFO:     127.0.0.1:52804 - "POST /chatbot/webhook HTTP/1.1" 200 OK
INFO:     127.0.0.1:52805 - "POST /insurance/verify HTTP/1.1" 400 Bad Request